<<< PROJECT PART I
<<< -- process set (n=3) with 1 CPU-bound process
<<< -- seed=32; lambda=0.001000; bound=1024
CPU-bound process A0: arrival time 319ms; 25 CPU bursts
I/O-bound process A1: arrival time 506ms; 5 CPU bursts
I/O-bound process A2: arrival time 821ms; 15 CPU bursts

<<< PROJECT PART II
<<< -- t_cs=4ms; alpha=0.75; t_slice=256ms
time 0ms: Simulator started for FCFS [Q empty]
time 319ms: Process A0 arrived; added to ready queue [Q A0]
time 321ms: Process A0 started using the CPU for 1448ms burst [Q empty]
time 506ms: Process A1 arrived; added to ready queue [Q A1]
time 821ms: Process A2 arrived; added to ready queue [Q A1 A2]
time 1769ms: Process A0 completed a CPU burst; 24 bursts to go [Q ]
time 1773ms: Process A1 started using the CPU for 971ms burst [Q empty]
time 2379ms: Process A0 completed I/O; added to ready queue [Q A1]
time 2746ms: Process A1 completed a CPU burst; 4 bursts to go [Q ]
time 2750ms: Process A2 started using the CPU for 408ms burst [Q empty]
time 3160ms: Process A2 completed a CPU burst; 14 bursts to go [Q A1]
time 3164ms: Process A0 started using the CPU for 316ms burst [Q empty]
time 3180ms: Process A1 completed I/O; added to ready queue [Q A2 A0]
time 3482ms: Process A0 completed a CPU burst; 23 bursts to go [Q A2]
time 3486ms: Process A1 started using the CPU for 129ms burst [Q empty]
time 3617ms: Process A1 completed a CPU burst; 3 bursts to go [Q A2 A0]
time 3958ms: Process A0 completed I/O; added to ready queue [Q A2 A1]
time 3958ms: Process A0 started using the CPU for 3556ms burst [Q empty]
time 4883ms: Process A1 completed I/O; added to ready queue [Q A2 A0]
time 7516ms: Process A0 completed a CPU burst; 22 bursts to go [Q A2]
time 7520ms: Process A1 started using the CPU for 188ms burst [Q empty]
time 7710ms: Process A1 completed a CPU burst; 2 bursts to go [Q A2 A0]
time 8482ms: Process A0 completed I/O; added to ready queue [Q A2 A1]
time 8482ms: Process A0 started using the CPU for 2516ms burst [Q empty]
time 8674ms: Process A2 completed I/O; added to ready queue [Q A1 A0]
time 9208ms: Process A1 completed I/O; added to ready queue [Q A0]
time 11000ms: Process A0 completed a CPU burst; 21 bursts to go [Q ]
time 11004ms: Process A2 started using the CPU for 182ms burst [Q empty]
time 11016ms: Process A0 completed I/O; added to ready queue [Q A2]
time 11188ms: Process A2 completed a CPU burst; 13 bursts to go [Q ]
time 11192ms: Process A1 started using the CPU for 302ms burst [Q empty]
time 11496ms: Process A1 completed a CPU burst; 1 bursts to go [Q A2]
time 11500ms: Process A0 started using the CPU for 732ms burst [Q empty]
time 12234ms: Process A0 completed a CPU burst; 20 bursts to go [Q A2 A1]
time 12826ms: Process A1 completed I/O; added to ready queue [Q A2 A0]
time 12826ms: Process A1 started using the CPU for 73ms burst [Q empty]
time 12899ms: Process A1 terminated [Q A2 A0]
time 12905ms: Process A0 completed I/O; added to ready queue [Q A2]
time 12905ms: Process A0 started using the CPU for 1872ms burst [Q empty]
time 14779ms: Process A0 completed a CPU burst; 19 bursts to go [Q A2]
time 14863ms: Process A0 completed I/O; added to ready queue [Q A2]
time 14863ms: Process A0 started using the CPU for 1020ms burst [Q empty]
time 14934ms: Process A2 completed I/O; added to ready queue [Q A0]
time 15885ms: Process A0 completed a CPU burst; 18 bursts to go [Q ]
time 15889ms: Process A2 started using the CPU for 89ms burst [Q empty]
time 15980ms: Process A2 completed a CPU burst; 12 bursts to go [Q A0]
time 15990ms: Process A2 completed I/O; added to ready queue [Q A0]
time 15990ms: Process A2 started using the CPU for 781ms burst [Q empty]
time 16373ms: Process A0 completed I/O; added to ready queue [Q A2]
time 16773ms: Process A2 completed a CPU burst; 11 bursts to go [Q ]
time 16777ms: Process A0 started using the CPU for 228ms burst [Q empty]
time 17007ms: Process A0 completed a CPU burst; 17 bursts to go [Q A2]
time 17031ms: Process A2 completed I/O; added to ready queue [Q A0]
time 17031ms: Process A2 started using the CPU for 107ms burst [Q empty]
time 17140ms: Process A2 completed a CPU burst; 10 bursts to go [Q A0]
time 17356ms: Process A0 completed I/O; added to ready queue [Q A2]
time 17356ms: Process A0 started using the CPU for 2092ms burst [Q empty]
time 17798ms: Process A2 completed I/O; added to ready queue [Q A0]
time 19450ms: Process A0 completed a CPU burst; 16 bursts to go [Q ]
time 19454ms: Process A2 started using the CPU for 65ms burst [Q empty]
time 19521ms: Process A2 completed a CPU burst; 9 bursts to go [Q A0]
time 19674ms: Process A0 completed I/O; added to ready queue [Q A2]
time 19674ms: Process A0 started using the CPU for 3380ms burst [Q empty]
time 23056ms: Process A0 completed a CPU burst; 15 bursts to go [Q A2]
time 23117ms: Process A0 completed I/O; added to ready queue [Q A2]
time 23117ms: Process A0 started using the CPU for 1700ms burst [Q empty]
time 24819ms: Process A0 completed a CPU burst; 14 bursts to go [Q A2]
time 24930ms: Process A0 completed I/O; added to ready queue [Q A2]
time 24930ms: Process A0 started using the CPU for 664ms burst [Q empty]
time 25395ms: Process A2 completed I/O; added to ready queue [Q A0]
time 25596ms: Process A0 completed a CPU burst; 13 bursts to go [Q ]
time 25600ms: Process A2 started using the CPU for 69ms burst [Q empty]
time 25671ms: Process A2 completed a CPU burst; 8 bursts to go [Q A0]
time 25930ms: Process A0 completed I/O; added to ready queue [Q A2]
time 25930ms: Process A0 started using the CPU for 916ms burst [Q empty]
time 26848ms: Process A0 completed a CPU burst; 12 bursts to go [Q A2]
time 27768ms: Process A0 completed I/O; added to ready queue [Q A2]
time 27768ms: Process A0 started using the CPU for 1988ms burst [Q empty]
time 29758ms: Process A0 completed a CPU burst; 11 bursts to go [Q A2]
time 30017ms: Process A2 completed I/O; added to ready queue [Q A0]
time 30017ms: Process A2 started using the CPU for 232ms burst [Q empty]
time 30251ms: Process A2 completed a CPU burst; 7 bursts to go [Q A0]
time 30527ms: Process A0 completed I/O; added to ready queue [Q A2]
time 30527ms: Process A0 started using the CPU for 3948ms burst [Q empty]
time 34477ms: Process A0 completed a CPU burst; 10 bursts to go [Q A2]
time 34900ms: Process A0 completed I/O; added to ready queue [Q A2]
time 34900ms: Process A0 started using the CPU for 340ms burst [Q empty]
time 35242ms: Process A0 completed a CPU burst; 9 bursts to go [Q A2]
time 35373ms: Process A2 completed I/O; added to ready queue [Q A0]
time 35373ms: Process A2 started using the CPU for 225ms burst [Q empty]
time 35600ms: Process A2 completed a CPU burst; 6 bursts to go [Q A0]
time 36005ms: Process A0 completed I/O; added to ready queue [Q A2]
time 36005ms: Process A0 started using the CPU for 2768ms burst [Q empty]
time 38775ms: Process A0 completed a CPU burst; 8 bursts to go [Q A2]
time 39047ms: Process A0 completed I/O; added to ready queue [Q A2]
time 39047ms: Process A0 started using the CPU for 1540ms burst [Q empty]
time 40290ms: Process A2 completed I/O; added to ready queue [Q A0]
time 40589ms: Process A0 completed a CPU burst; 7 bursts to go [Q ]
time 40593ms: Process A2 started using the CPU for 42ms burst [Q empty]
time 40637ms: Process A2 completed a CPU burst; 5 bursts to go [Q A0]
time 40740ms: Process A0 completed I/O; added to ready queue [Q A2]
time 40740ms: Process A0 started using the CPU for 1552ms burst [Q empty]
time 42294ms: Process A0 completed a CPU burst; 6 bursts to go [Q A2]
time 42380ms: Process A0 completed I/O; added to ready queue [Q A2]
time 42380ms: Process A0 started using the CPU for 224ms burst [Q empty]
time 42606ms: Process A0 completed a CPU burst; 5 bursts to go [Q A2]
time 43258ms: Process A0 completed I/O; added to ready queue [Q A2]
time 43258ms: Process A0 started using the CPU for 52ms burst [Q empty]
time 43312ms: Process A0 completed a CPU burst; 4 bursts to go [Q A2]
time 43392ms: Process A0 completed I/O; added to ready queue [Q A2]
time 43392ms: Process A0 started using the CPU for 3548ms burst [Q empty]
time 46942ms: Process A0 completed a CPU burst; 3 bursts to go [Q A2]
time 47085ms: Process A0 completed I/O; added to ready queue [Q A2]
time 47085ms: Process A0 started using the CPU for 820ms burst [Q empty]
time 47907ms: Process A0 completed a CPU burst; 2 bursts to go [Q A2]
time 48143ms: Process A2 completed I/O; added to ready queue [Q A0]
time 48143ms: Process A2 started using the CPU for 335ms burst [Q empty]
time 48480ms: Process A2 completed a CPU burst; 4 bursts to go [Q A0]
time 48914ms: Process A0 completed I/O; added to ready queue [Q A2]
time 48914ms: Process A0 started using the CPU for 920ms burst [Q empty]
time 49836ms: Process A0 completed a CPU burst; 1 bursts to go [Q A2]
time 50286ms: Process A0 completed I/O; added to ready queue [Q A2]
time 50286ms: Process A0 started using the CPU for 1876ms burst [Q empty]
time 52162ms: Process A0 terminated [Q A2]
time 53474ms: Process A2 completed I/O; added to ready queue [Q ]
time 53474ms: Process A2 started using the CPU for 247ms burst [Q empty]
time 53723ms: Process A2 completed a CPU burst; 3 bursts to go [Q ]
time 59685ms: Process A2 completed I/O; added to ready queue [Q ]
time 59685ms: Process A2 started using the CPU for 66ms burst [Q empty]
time 59753ms: Process A2 completed a CPU burst; 2 bursts to go [Q ]
time 59819ms: Process A2 completed I/O; added to ready queue [Q ]
time 59819ms: Process A2 started using the CPU for 155ms burst [Q empty]
time 59976ms: Process A2 completed a CPU burst; 1 bursts to go [Q ]
time 65738ms: Process A2 completed I/O; added to ready queue [Q ]
time 65738ms: Process A2 started using the CPU for 280ms burst [Q empty]
time 66018ms: Process A2 terminated [Q ]
time 0ms: Simulator started for SJF [Qempty]
